Workbook

Sheet 01_売上入力
A1: 01 売上入力シート ― 日々の販売データを入力してください
A2: 日付 | B2: 曜日 | C2: 時間帯 | D2: 商品名 | E2: 数量 | F2: 単価 (円) | G2: 売上 (円)
A3: 45444 | B3: 土 | C3: 8-9 | D3: 食パン（1斤） | E3: 3 | F3: 350 | G3: =E3*F3
A4: 45444 | B4: 土 | C4: 8-9 | D4: クロワッサン | E4: 5 | F4: 250 | G4: =E4*F4
A5: 45444 | B5: 土 | C5: 9-10 | D5: ベーグル（プレーン） | E5: 4 | F5: 200 | G5: =E5*F5
A6: 45444 | B6: 土 | C6: 9-10 | D6: カレーパン | E6: 6 | F6: 220 | G6: =E6*F6
A7: 45444 | B7: 土 | C7: 10-11 | D7: メロンパン | E7: 8 | F7: 200 | G7: =E7*F7
A8: 45444 | B8: 土 | C8: 10-11 | D8: 食パン（1斤） | E8: 2 | F8: 350 | G8: =E8*F8
A9: 45444 | B9: 土 | C9: 11-12 | D9: カレーパン | E9: 3 | F9: 220 | G9: =E9*F9
A10: 45444 | B10: 土 | C10: 11-12 | D10: クロワッサン | E10: 2 | F10: 250 | G10: =E10*F10
A11: 45445 | B11: 日 | C11: 8-9 | D11: 食パン（1斤） | E11: 4 | F11: 350 | G11: =E11*F11
A12: 45445 | B12: 日 | C12: 9-10 | D12: ベーグル（プレーン） | E12: 3 | F12: 200 | G12: =E12*F12
A13: 45445 | B13: 日 | C13: 9-10 | D13: メロンパン | E13: 5 | F13: 200 | G13: =E13*F13
A14: 45445 | B14: 日 | C14: 10-11 | D14: カレーパン | E14: 4 | F14: 220 | G14: =E14*F14
... A17: 45446 | B17: 月 | C17: 10-11 | D17: カレーパン | E17: 2 | F17: 220 | G17: =E17*F17
G18: =IF(E18="","",E18*F18)
G19: =IF(E19="","",E19*F19)
G20: =IF(E20="","",E20*F20)
G21: =IF(E21="","",E21*F21)
G22: =IF(E22="","",E22*F22)
G23: =IF(E23="","",E23*F23)
G24: =IF(E24="","",E24*F24)
G25: =IF(E25="","",E25*F25)
G26: =IF(E26="","",E26*F26)
G27: =IF(E27="","",E27*F27)
G28: =IF(E28="","",E28*F28)
G29: =IF(E29="","",E29*F29)
... G51: =IF(E51="","",E51*F51)

Sheet 02_商品マスタ
A1: 02 商品マスタ ― 商品情報・粗利を一元管理
A2: 商品ID | B2: 商品名 | C2: カテゴリ | D2: 販売価格 (円) | E2: 原価 (円) | F2: 粗利 (円) | G2: 製造時間 (分) | H2: 推奨製造数 | I2: 粗利率
A3: P001 | B3: 食パン（1斤） | C3: 食パン | D3: 350 | E3: 120 | F3: =D3-E3 | G3: 15 | H3: 8 | I3: =IFERROR(F3/D3,0)
A4: P002 | B4: ベーグル（プレーン） | C4: ベーグル | D4: 200 | E4: 70 | F4: =D4-E4 | G4: 20 | H4: 10 | I4: =IFERROR(F4/D4,0)
A5: P003 | B5: クロワッサン | C5: クロワッサン | D5: 250 | E5: 110 | F5: =D5-E5 | G5: 35 | H5: 6 | I5: =IFERROR(F5/D5,0)
A6: P004 | B6: カレーパン | C6: 惣菜パン | D6: 220 | E6: 85 | F6: =D6-E6 | G6: 25 | H6: 8 | I6: =IFERROR(F6/D6,0)
A7: P005 | B7: メロンパン | C7: 菓子パン | D7: 200 | E7: 65 | F7: =D7-E7 | G7: 20 | H7: 10 | I7: =IFERROR(F7/D7,0)
A8: P006 | B8: チョコデニッシュ | C8: 菓子パン | D8: 230 | E8: 90 | F8: =D8-E8 | G8: 30 | H8: 6 | I8: =IFERROR(F8/D8,0)
A9: P007 | B9: バゲット | C9: 食パン | D9: 400 | E9: 130 | F9: =D9-E9 | G9: 25 | H9: 5 | I9: =IFERROR(F9/D9,0)
A10: P008 | B10: シナモンロール | C10: 焼き菓子 | D10: 280 | E10: 100 | F10: =D10-E10 | G10: 30 | H10: 8 | I10: =IFERROR(F10/D10,0)

Sheet 03_原価管理
A1: 03 原価管理 ― 材料ごとの原価内訳を管理
A2: 商品名 | B2: 小麦 (円) | C2: バター (円) | D2: 包材 (円) | E2: その他 (円) | F2: 合計原価 (円)
A3: 食パン（1斤） | B3: 45 | C3: 20 | D3: 12 | E3: 10 | F3: =SUM(B3:E3)
A4: ベーグル（プレーン） | B4: 25 | C4: 10 | D4: 10 | E4: 8 | F4: =SUM(B4:E4)
A5: クロワッサン | B5: 30 | C5: 45 | D5: 15 | E5: 12 | F5: =SUM(B5:E5)
A6: カレーパン | B6: 28 | C6: 15 | D6: 15 | E6: 15 | F6: =SUM(B6:E6)
A7: メロンパン | B7: 25 | C7: 12 | D7: 12 | E7: 8 | F7: =SUM(B7:E7)
A8: チョコデニッシュ | B8: 28 | C8: 25 | D8: 15 | E8: 14 | F8: =SUM(B8:E8)
A9: バゲット | B9: 50 | C9: 15 | D9: 15 | E9: 12 | F9: =SUM(B9:E9)
A10: シナモンロール | B10: 30 | C10: 30 | D10: 15 | E10: 12 | F10: =SUM(B10:E10)

Sheet 04_廃棄入力
A1: 04 廃棄入力 ― 廃棄した商品を記録
A2: 日付 | B2: 商品名 | C2: 廃棄数 | D2: 販売価格 (円) | E2: 廃棄金額 (円)
A3: 45444 | B3: クロワッサン | C3: 2 | D3: 250 | E3: =C3*D3
A4: 45444 | B4: メロンパン | C4: 3 | D4: 200 | E4: =C4*D4
A5: 45445 | B5: シナモンロール | C5: 4 | D5: 280 | E5: =C5*D5
A6: 45445 | B6: チョコデニッシュ | C6: 2 | D6: 230 | E6: =C6*D6
A7: 45446 | B7: クロワッサン | C7: 1 | D7: 250 | E7: =C7*D7
E8: =IF(C8="","",C8*D8)
E9: =IF(C9="","",C9*D9)
E10: =IF(C10="","",C10*D10)
E11: =IF(C11="","",C11*D11)
E12: =IF(C12="","",C12*D12)
E13: =IF(C13="","",C13*D13)
E14: =IF(C14="","",C14*D14)
E15: =IF(C15="","",C15*D15)
E16: =IF(C16="","",C16*D16)
E17: =IF(C17="","",C17*D17)
E18: =IF(C18="","",C18*D18)
E19: =IF(C19="","",C19*D19)
... E51: =IF(C51="","",C51*D51)

Sheet 05_製造時間
A1: 05 製造時間 ― 商品ごとの工程時間と作業負荷を管理
A2: 商品名 | B2: 仕込み時間 | C2: 成形時間 | D2: 焼成時間 | E2: 合計時間（分） | F2: 作業人数 | G2: 粗利/時間 (円/時)
A3: 食パン（1斤） | B3: 30 | C3: 10 | D3: 50 | E3: =SUM(B3:D3) | F3: 1 | G3: =IFERROR((XLOOKUP(A3,'02_商品マスタ'!B:B,'02_商品マスタ'!F:F,0))/(E3/60),0)
A4: ベーグル（プレーン） | B4: 30 | C4: 20 | D4: 25 | E4: =SUM(B4:D4) | F4: 1 | G4: =IFERROR((XLOOKUP(A4,'02_商品マスタ'!B:B,'02_商品マスタ'!F:F,0))/(E4/60),0)
A5: クロワッサン | B5: 60 | C5: 40 | D5: 20 | E5: =SUM(B5:D5) | F5: 2 | G5: =IFERROR((XLOOKUP(A5,'02_商品マスタ'!B:B,'02_商品マスタ'!F:F,0))/(E5/60),0)
A6: カレーパン | B6: 30 | C6: 30 | D6: 20 | E6: =SUM(B6:D6) | F6: 1 | G6: =IFERROR((XLOOKUP(A6,'02_商品マスタ'!B:B,'02_商品マスタ'!F:F,0))/(E6/60),0)
A7: メロンパン | B7: 30 | C7: 25 | D7: 15 | E7: =SUM(B7:D7) | F7: 1 | G7: =IFERROR((XLOOKUP(A7,'02_商品マスタ'!B:B,'02_商品マスタ'!F:F,0))/(E7/60),0)
A8: チョコデニッシュ | B8: 45 | C8: 30 | D8: 20 | E8: =SUM(B8:D8) | F8: 2 | G8: =IFERROR((XLOOKUP(A8,'02_商品マスタ'!B:B,'02_商品マスタ'!F:F,0))/(E8/60),0)
A9: バゲット | B9: 20 | C9: 10 | D9: 30 | E9: =SUM(B9:D9) | F9: 1 | G9: =IFERROR((XLOOKUP(A9,'02_商品マスタ'!B:B,'02_商品マスタ'!F:F,0))/(E9/60),0)
A10: シナモンロール | B10: 40 | C10: 20 | D10: 25 | E10: =SUM(B10:D10) | F10: 1 | G10: =IFERROR((XLOOKUP(A10,'02_商品マスタ'!B:B,'02_商品マスタ'!F:F,0))/(E10/60),0)

Sheet 06_人件費
A1: 06 人件費 ― シフト・労働時間・人件費を記録
A2: 日付 | B2: スタッフ名 | C2: 出勤 | D2: 退勤 | E2: 時給 (円) | F2: 労働時間 (h) | G2: 人件費 (円)
A3: 45444 | B3: 田中 花子 | C3: 0.25 | D3: 0.58333333 | E3: 1050 | F3: =(D3-C3)*24 | G3: =F3*E3
A4: 45444 | B4: 鈴木 太郎 | C4: 0.33333333 | D4: 0.66666667 | E4: 1000 | F4: =(D4-C4)*24 | G4: =F4*E4
A5: 45445 | B5: 田中 花子 | C5: 0.25 | D5: 0.58333333 | E5: 1050 | F5: =(D5-C5)*24 | G5: =F5*E5
A6: 45446 | B6: 鈴木 太郎 | C6: 0.29166667 | D6: 0.625 | E6: 1000 | F6: =(D6-C6)*24 | G6: =F6*E6
F7: =IFERROR((D7-C7)*24,"") | G7: =IFERROR(F7*E7,"")
F8: =IFERROR((D8-C8)*24,"") | G8: =IFERROR(F8*E8,"")
F9: =IFERROR((D9-C9)*24,"") | G9: =IFERROR(F9*E9,"")
F10: =IFERROR((D10-C10)*24,"") | G10: =IFERROR(F10*E10,"")
F11: =IFERROR((D11-C11)*24,"") | G11: =IFERROR(F11*E11,"")
F12: =IFERROR((D12-C12)*24,"") | G12: =IFERROR(F12*E12,"")
F13: =IFERROR((D13-C13)*24,"") | G13: =IFERROR(F13*E13,"")
F14: =IFERROR((D14-C14)*24,"") | G14: =IFERROR(F14*E14,"")
F15: =IFERROR((D15-C15)*24,"") | G15: =IFERROR(F15*E15,"")
F16: =IFERROR((D16-C16)*24,"") | G16: =IFERROR(F16*E16,"")
F17: =IFERROR((D17-C17)*24,"") | G17: =IFERROR(F17*E17,"")
F18: =IFERROR((D18-C18)*24,"") | G18: =IFERROR(F18*E18,"")
... F51: =IFERROR((D51-C51)*24,"") | G51: =IFERROR(F51*E51,"")

Sheet 07_分析ダッシュボード
A1: 07 分析ダッシュボード ― 自動集計・可視化
A3: ■ KPI サマリ（累計） | E3: ■ 商品別売上ランキング
A4: 指標 | B4: 値 | E4: 商品名 | F4: 売上 (円) | G4: 販売数 | H4: 廃棄数 | I4: 粗利 (円)
A5: 総売上合計 (円) | B5: =IFERROR(SUM('01_売上入力'!G3:G200),0) | E5: 食パン（1斤） | F5: =IFERROR(SUMIF('01_売上入力'!D:D,E5,'01_売上入力'!G:G),0) | G5: =IFERROR(SUMIF('01_売上入力'!D:D,E5,'01_売上入力'!E:E),0) | H5: =IFERROR(SUMIF('04_廃棄入力'!B:B,E5,'04_廃棄入力'!C:C),0) | I5: =IFERROR(F5-XLOOKUP(E5,'02_商品マスタ'!B:B,'02_商品マスタ'!E:E,0)*H5,0)
A6: 総販売個数 | B6: =IFERROR(SUM('01_売上入力'!E3:E200),0) | E6: ベーグル（プレーン） | F6: =IFERROR(SUMIF('01_売上入力'!D:D,E6,'01_売上入力'!G:G),0) | G6: =IFERROR(SUMIF('01_売上入力'!D:D,E6,'01_売上入力'!E:E),0) | H6: =IFERROR(SUMIF('04_廃棄入力'!B:B,E6,'04_廃棄入力'!C:C),0) | I6: =IFERROR(F6-XLOOKUP(E6,'02_商品マスタ'!B:B,'02_商品マスタ'!E:E,0)*H6,0)
A7: 総廃棄金額 (円) | B7: =IFERROR(SUM('04_廃棄入力'!E3:E200),0) | E7: クロワッサン | F7: =IFERROR(SUMIF('01_売上入力'!D:D,E7,'01_売上入力'!G:G),0) | G7: =IFERROR(SUMIF('01_売上入力'!D:D,E7,'01_売上入力'!E:E),0) | H7: =IFERROR(SUMIF('04_廃棄入力'!B:B,E7,'04_廃棄入力'!C:C),0) | I7: =IFERROR(F7-XLOOKUP(E7,'02_商品マスタ'!B:B,'02_商品マスタ'!E:E,0)*H7,0)
A8: 総人件費 (円) | B8: =IFERROR(SUM('06_人件費'!G3:G200),0) | E8: カレーパン | F8: =IFERROR(SUMIF('01_売上入力'!D:D,E8,'01_売上入力'!G:G),0) | G8: =IFERROR(SUMIF('01_売上入力'!D:D,E8,'01_売上入力'!E:E),0) | H8: =IFERROR(SUMIF('04_廃棄入力'!B:B,E8,'04_廃棄入力'!C:C),0) | I8: =IFERROR(F8-XLOOKUP(E8,'02_商品マスタ'!B:B,'02_商品マスタ'!E:E,0)*H8,0)
A9: 粗利合計 (円) | B9: =IFERROR(B5-B7-B8,0) | E9: メロンパン | F9: =IFERROR(SUMIF('01_売上入力'!D:D,E9,'01_売上入力'!G:G),0) | G9: =IFERROR(SUMIF('01_売上入力'!D:D,E9,'01_売上入力'!E:E),0) | H9: =IFERROR(SUMIF('04_廃棄入力'!B:B,E9,'04_廃棄入力'!C:C),0) | I9: =IFERROR(F9-XLOOKUP(E9,'02_商品マスタ'!B:B,'02_商品マスタ'!E:E,0)*H9,0)
A10: 客単価 (円/人) | B10: =IFERROR(B5/SUM(日次サマリ!B3:B200),"-") | E10: チョコデニッシュ | F10: =IFERROR(SUMIF('01_売上入力'!D:D,E10,'01_売上入力'!G:G),0) | G10: =IFERROR(SUMIF('01_売上入力'!D:D,E10,'01_売上入力'!E:E),0) | H10: =IFERROR(SUMIF('04_廃棄入力'!B:B,E10,'04_廃棄入力'!C:C),0) | I10: =IFERROR(F10-XLOOKUP(E10,'02_商品マスタ'!B:B,'02_商品マスタ'!E:E,0)*H10,0)
E11: バゲット | F11: =IFERROR(SUMIF('01_売上入力'!D:D,E11,'01_売上入力'!G:G),0) | G11: =IFERROR(SUMIF('01_売上入力'!D:D,E11,'01_売上入力'!E:E),0) | H11: =IFERROR(SUMIF('04_廃棄入力'!B:B,E11,'04_廃棄入力'!C:C),0) | I11: =IFERROR(F11-XLOOKUP(E11,'02_商品マスタ'!B:B,'02_商品マスタ'!E:E,0)*H11,0)
E12: シナモンロール | F12: =IFERROR(SUMIF('01_売上入力'!D:D,E12,'01_売上入力'!G:G),0) | G12: =IFERROR(SUMIF('01_売上入力'!D:D,E12,'01_売上入力'!E:E),0) | H12: =IFERROR(SUMIF('04_廃棄入力'!B:B,E12,'04_廃棄入力'!C:C),0) | I12: =IFERROR(F12-XLOOKUP(E12,'02_商品マスタ'!B:B,'02_商品マスタ'!E:E,0)*H12,0)
A13: ■ 時間帯別売上
A14: 時間帯 | B14: 売上 (円) | C14: 販売数
A15: 8-9 | B15: =IFERROR(SUMIF('01_売上入力'!C:C,A15,'01_売上入力'!G:G),0) | C15: =IFERROR(SUMIF('01_売上入力'!C:C,A15,'01_売上入力'!E:E),0)
A16: 9-10 | B16: =IFERROR(SUMIF('01_売上入力'!C:C,A16,'01_売上入力'!G:G),0) | C16: =IFERROR(SUMIF('01_売上入力'!C:C,A16,'01_売上入力'!E:E),0)
A17: 10-11 | B17: =IFERROR(SUMIF('01_売上入力'!C:C,A17,'01_売上入力'!G:G),0) | C17: =IFERROR(SUMIF('01_売上入力'!C:C,A17,'01_売上入力'!E:E),0)
A18: 11-12 | B18: =IFERROR(SUMIF('01_売上入力'!C:C,A18,'01_売上入力'!G:G),0) | C18: =IFERROR(SUMIF('01_売上入力'!C:C,A18,'01_売上入力'!E:E),0)
A19: 12-13 | B19: =IFERROR(SUMIF('01_売上入力'!C:C,A19,'01_売上入力'!G:G),0) | C19: =IFERROR(SUMIF('01_売上入力'!C:C,A19,'01_売上入力'!E:E),0)
A20: 13-14 | B20: =IFERROR(SUMIF('01_売上入力'!C:C,A20,'01_売上入力'!G:G),0) | C20: =IFERROR(SUMIF('01_売上入力'!C:C,A20,'01_売上入力'!E:E),0)
A21: 14-15 | B21: =IFERROR(SUMIF('01_売上入力'!C:C,A21,'01_売上入力'!G:G),0) | C21: =IFERROR(SUMIF('01_売上入力'!C:C,A21,'01_売上入力'!E:E),0)
A22: 15-16 | B22: =IFERROR(SUMIF('01_売上入力'!C:C,A22,'01_売上入力'!G:G),0) | C22: =IFERROR(SUMIF('01_売上入力'!C:C,A22,'01_売上入力'!E:E),0)

Sheet 日次サマリ
A1: 日次サマリ ― 日別：売上・客数・客単価・販売個数
A2: 日付 | B2: 客数（手入力） | C2: 日売上 (円) | D2: 販売個数 | E2: 客単価 (円/人) | F2: 廃棄金額 (円)
A3: 45444 | B3: 42 | C3: =IFERROR(SUMIFS('01_売上入力'!G:G,'01_売上入力'!A:A,A3),0) | D3: =IFERROR(SUMIFS('01_売上入力'!E:E,'01_売上入力'!A:A,A3),0) | E3: =IFERROR(IF(B3=0,"-",C3/B3),"-") | F3: =IFERROR(SUMIFS('04_廃棄入力'!E:E,'04_廃棄入力'!A:A,A3),0)
A4: 45445 | B4: 38 | C4: =IFERROR(SUMIFS('01_売上入力'!G:G,'01_売上入力'!A:A,A4),0) | D4: =IFERROR(SUMIFS('01_売上入力'!E:E,'01_売上入力'!A:A,A4),0) | E4: =IFERROR(IF(B4=0,"-",C4/B4),"-") | F4: =IFERROR(SUMIFS('04_廃棄入力'!E:E,'04_廃棄入力'!A:A,A4),0)
A5: 45446 | B5: 25 | C5: =IFERROR(SUMIFS('01_売上入力'!G:G,'01_売上入力'!A:A,A5),0) | D5: =IFERROR(SUMIFS('01_売上入力'!E:E,'01_売上入力'!A:A,A5),0) | E5: =IFERROR(IF(B5=0,"-",C5/B5),"-") | F5: =IFERROR(SUMIFS('04_廃棄入力'!E:E,'04_廃棄入力'!A:A,A5),0)
C6: =IFERROR(SUMIFS('01_売上入力'!G:G,'01_売上入力'!A:A,A6),"") | D6: =IFERROR(SUMIFS('01_売上入力'!E:E,'01_売上入力'!A:A,A6),"") | E6: =IFERROR(IF(B6="","",IF(B6=0,"-",C6/B6)),"") | F6: =IFERROR(SUMIFS('04_廃棄入力'!E:E,'04_廃棄入力'!A:A,A6),"")
C7: =IFERROR(SUMIFS('01_売上入力'!G:G,'01_売上入力'!A:A,A7),"") | D7: =IFERROR(SUMIFS('01_売上入力'!E:E,'01_売上入力'!A:A,A7),"") | E7: =IFERROR(IF(B7="","",IF(B7=0,"-",C7/B7)),"") | F7: =IFERROR(SUMIFS('04_廃棄入力'!E:E,'04_廃棄入力'!A:A,A7),"")
C8: =IFERROR(SUMIFS('01_売上入力'!G:G,'01_売上入力'!A:A,A8),"") | D8: =IFERROR(SUMIFS('01_売上入力'!E:E,'01_売上入力'!A:A,A8),"") | E8: =IFERROR(IF(B8="","",IF(B8=0,"-",C8/B8)),"") | F8: =IFERROR(SUMIFS('04_廃棄入力'!E:E,'04_廃棄入力'!A:A,A8),"")
C9: =IFERROR(SUMIFS('01_売上入力'!G:G,'01_売上入力'!A:A,A9),"") | D9: =IFERROR(SUMIFS('01_売上入力'!E:E,'01_売上入力'!A:A,A9),"") | E9: =IFERROR(IF(B9="","",IF(B9=0,"-",C9/B9)),"") | F9: =IFERROR(SUMIFS('04_廃棄入力'!E:E,'04_廃棄入力'!A:A,A9),"")
C10: =IFERROR(SUMIFS('01_売上入力'!G:G,'01_売上入力'!A:A,A10),"") | D10: =IFERROR(SUMIFS('01_売上入力'!E:E,'01_売上入力'!A:A,A10),"") | E10: =IFERROR(IF(B10="","",IF(B10=0,"-",C10/B10)),"") | F10: =IFERROR(SUMIFS('04_廃棄入力'!E:E,'04_廃棄入力'!A:A,A10),"")
C11: =IFERROR(SUMIFS('01_売上入力'!G:G,'01_売上入力'!A:A,A11),"") | D11: =IFERROR(SUMIFS('01_売上入力'!E:E,'01_売上入力'!A:A,A11),"") | E11: =IFERROR(IF(B11="","",IF(B11=0,"-",C11/B11)),"") | F11: =IFERROR(SUMIFS('04_廃棄入力'!E:E,'04_廃棄入力'!A:A,A11),"")
C12: =IFERROR(SUMIFS('01_売上入力'!G:G,'01_売上入力'!A:A,A12),"") | D12: =IFERROR(SUMIFS('01_売上入力'!E:E,'01_売上入力'!A:A,A12),"") | E12: =IFERROR(IF(B12="","",IF(B12=0,"-",C12/B12)),"") | F12: =IFERROR(SUMIFS('04_廃棄入力'!E:E,'04_廃棄入力'!A:A,A12),"")
C13: =IFERROR(SUMIFS('01_売上入力'!G:G,'01_売上入力'!A:A,A13),"") | D13: =IFERROR(SUMIFS('01_売上入力'!E:E,'01_売上入力'!A:A,A13),"") | E13: =IFERROR(IF(B13="","",IF(B13=0,"-",C13/B13)),"") | F13: =IFERROR(SUMIFS('04_廃棄入力'!E:E,'04_廃棄入力'!A:A,A13),"")
C14: =IFERROR(SUMIFS('01_売上入力'!G:G,'01_売上入力'!A:A,A14),"") | D14: =IFERROR(SUMIFS('01_売上入力'!E:E,'01_売上入力'!A:A,A14),"") | E14: =IFERROR(IF(B14="","",IF(B14=0,"-",C14/B14)),"") | F14: =IFERROR(SUMIFS('04_廃棄入力'!E:E,'04_廃棄入力'!A:A,A14),"")
C15: =IFERROR(SUMIFS('01_売上入力'!G:G,'01_売上入力'!A:A,A15),"") | D15: =IFERROR(SUMIFS('01_売上入力'!E:E,'01_売上入力'!A:A,A15),"") | E15: =IFERROR(IF(B15="","",IF(B15=0,"-",C15/B15)),"") | F15: =IFERROR(SUMIFS('04_廃棄入力'!E:E,'04_廃棄入力'!A:A,A15),"")
C16: =IFERROR(SUMIFS('01_売上入力'!G:G,'01_売上入力'!A:A,A16),"") | D16: =IFERROR(SUMIFS('01_売上入力'!E:E,'01_売上入力'!A:A,A16),"") | E16: =IFERROR(IF(B16="","",IF(B16=0,"-",C16/B16)),"") | F16: =IFERROR(SUMIFS('04_廃棄入力'!E:E,'04_廃棄入力'!A:A,A16),"")
C17: =IFERROR(SUMIFS('01_売上入力'!G:G,'01_売上入力'!A:A,A17),"") | D17: =IFERROR(SUMIFS('01_売上入力'!E:E,'01_売上入力'!A:A,A17),"") | E17: =IFERROR(IF(B17="","",IF(B17=0,"-",C17/B17)),"") | F17: =IFERROR(SUMIFS('04_廃棄入力'!E:E,'04_廃棄入力'!A:A,A17),"")
... C202: =IFERROR(SUMIFS('01_売上入力'!G:G,'01_売上入力'!A:A,A202),"") | D202: =IFERROR(SUMIFS('01_売上入力'!E:E,'01_売上入力'!A:A,A202),"") | E202: =IFERROR(IF(B202="","",IF(B202=0,"-",C202/B202)),"") | F202: =IFERROR(SUMIFS('04_廃棄入力'!E:E,'04_廃棄入力'!A:A,A202),"")

Sheet 月次サマリ
A1: 月次サマリ ― 月別：月商・客数・客単価・廃棄率
A2: 年月 | B2: 月商 (円) | C2: 販売個数 | D2: 客数 | E2: 客単価 (円/人) | F2: 廃棄金額 (円)
A3: 2024/06 | B3: =IFERROR(SUMPRODUCT((TEXT('01_売上入力'!A3:A200,"YYYY/MM")=A3)*('01_売上入力'!G3:G200)),0) | C3: =IFERROR(SUMPRODUCT((TEXT('01_売上入力'!A3:A200,"YYYY/MM")=A3)*('01_売上入力'!E3:E200)),0) | D3: =IFERROR(IF(D3=0,"-",B3/D3),"-") | E3: =IFERROR(SUMPRODUCT((TEXT('04_廃棄入力'!A3:A200,"YYYY/MM")=A3)*('04_廃棄入力'!E3:E200)),0)
B4: =IFERROR(SUMPRODUCT((TEXT('01_売上入力'!A3:A200,"YYYY/MM")=A4)*('01_売上入力'!G3:G200)),"") | C4: =IFERROR(SUMPRODUCT((TEXT('01_売上入力'!A3:A200,"YYYY/MM")=A4)*('01_売上入力'!E3:E200)),"") | E4: =IFERROR(IF(D4="","",IF(D4=0,"-",B4/D4)),"") | F4: =IFERROR(SUMPRODUCT((TEXT('04_廃棄入力'!A3:A200,"YYYY/MM")=A4)*('04_廃棄入力'!E3:E200)),"")
B5: =IFERROR(SUMPRODUCT((TEXT('01_売上入力'!A3:A200,"YYYY/MM")=A5)*('01_売上入力'!G3:G200)),"") | C5: =IFERROR(SUMPRODUCT((TEXT('01_売上入力'!A3:A200,"YYYY/MM")=A5)*('01_売上入力'!E3:E200)),"") | E5: =IFERROR(IF(D5="","",IF(D5=0,"-",B5/D5)),"") | F5: =IFERROR(SUMPRODUCT((TEXT('04_廃棄入力'!A3:A200,"YYYY/MM")=A5)*('04_廃棄入力'!E3:E200)),"")
B6: =IFERROR(SUMPRODUCT((TEXT('01_売上入力'!A3:A200,"YYYY/MM")=A6)*('01_売上入力'!G3:G200)),"") | C6: =IFERROR(SUMPRODUCT((TEXT('01_売上入力'!A3:A200,"YYYY/MM")=A6)*('01_売上入力'!E3:E200)),"") | E6: =IFERROR(IF(D6="","",IF(D6=0,"-",B6/D6)),"") | F6: =IFERROR(SUMPRODUCT((TEXT('04_廃棄入力'!A3:A200,"YYYY/MM")=A6)*('04_廃棄入力'!E3:E200)),"")
B7: =IFERROR(SUMPRODUCT((TEXT('01_売上入力'!A3:A200,"YYYY/MM")=A7)*('01_売上入力'!G3:G200)),"") | C7: =IFERROR(SUMPRODUCT((TEXT('01_売上入力'!A3:A200,"YYYY/MM")=A7)*('01_売上入力'!E3:E200)),"") | E7: =IFERROR(IF(D7="","",IF(D7=0,"-",B7/D7)),"") | F7: =IFERROR(SUMPRODUCT((TEXT('04_廃棄入力'!A3:A200,"YYYY/MM")=A7)*('04_廃棄入力'!E3:E200)),"")
B8: =IFERROR(SUMPRODUCT((TEXT('01_売上入力'!A3:A200,"YYYY/MM")=A8)*('01_売上入力'!G3:G200)),"") | C8: =IFERROR(SUMPRODUCT((TEXT('01_売上入力'!A3:A200,"YYYY/MM")=A8)*('01_売上入力'!E3:E200)),"") | E8: =IFERROR(IF(D8="","",IF(D8=0,"-",B8/D8)),"") | F8: =IFERROR(SUMPRODUCT((TEXT('04_廃棄入力'!A3:A200,"YYYY/MM")=A8)*('04_廃棄入力'!E3:E200)),"")
B9: =IFERROR(SUMPRODUCT((TEXT('01_売上入力'!A3:A200,"YYYY/MM")=A9)*('01_売上入力'!G3:G200)),"") | C9: =IFERROR(SUMPRODUCT((TEXT('01_売上入力'!A3:A200,"YYYY/MM")=A9)*('01_売上入力'!E3:E200)),"") | E9: =IFERROR(IF(D9="","",IF(D9=0,"-",B9/D9)),"") | F9: =IFERROR(SUMPRODUCT((TEXT('04_廃棄入力'!A3:A200,"YYYY/MM")=A9)*('04_廃棄入力'!E3:E200)),"")
B10: =IFERROR(SUMPRODUCT((TEXT('01_売上入力'!A3:A200,"YYYY/MM")=A10)*('01_売上入力'!G3:G200)),"") | C10: =IFERROR(SUMPRODUCT((TEXT('01_売上入力'!A3:A200,"YYYY/MM")=A10)*('01_売上入力'!E3:E200)),"") | E10: =IFERROR(IF(D10="","",IF(D10=0,"-",B10/D10)),"") | F10: =IFERROR(SUMPRODUCT((TEXT('04_廃棄入力'!A3:A200,"YYYY/MM")=A10)*('04_廃棄入力'!E3:E200)),"")
B11: =IFERROR(SUMPRODUCT((TEXT('01_売上入力'!A3:A200,"YYYY/MM")=A11)*('01_売上入力'!G3:G200)),"") | C11: =IFERROR(SUMPRODUCT((TEXT('01_売上入力'!A3:A200,"YYYY/MM")=A11)*('01_売上入力'!E3:E200)),"") | E11: =IFERROR(IF(D11="","",IF(D11=0,"-",B11/D11)),"") | F11: =IFERROR(SUMPRODUCT((TEXT('04_廃棄入力'!A3:A200,"YYYY/MM")=A11)*('04_廃棄入力'!E3:E200)),"")
B12: =IFERROR(SUMPRODUCT((TEXT('01_売上入力'!A3:A200,"YYYY/MM")=A12)*('01_売上入力'!G3:G200)),"") | C12: =IFERROR(SUMPRODUCT((TEXT('01_売上入力'!A3:A200,"YYYY/MM")=A12)*('01_売上入力'!E3:E200)),"") | E12: =IFERROR(IF(D12="","",IF(D12=0,"-",B12/D12)),"") | F12: =IFERROR(SUMPRODUCT((TEXT('04_廃棄入力'!A3:A200,"YYYY/MM")=A12)*('04_廃棄入力'!E3:E200)),"")
B13: =IFERROR(SUMPRODUCT((TEXT('01_売上入力'!A3:A200,"YYYY/MM")=A13)*('01_売上入力'!G3:G200)),"") | C13: =IFERROR(SUMPRODUCT((TEXT('01_売上入力'!A3:A200,"YYYY/MM")=A13)*('01_売上入力'!E3:E200)),"") | E13: =IFERROR(IF(D13="","",IF(D13=0,"-",B13/D13)),"") | F13: =IFERROR(SUMPRODUCT((TEXT('04_廃棄入力'!A3:A200,"YYYY/MM")=A13)*('04_廃棄入力'!E3:E200)),"")
B14: =IFERROR(SUMPRODUCT((TEXT('01_売上入力'!A3:A200,"YYYY/MM")=A14)*('01_売上入力'!G3:G200)),"") | C14: =IFERROR(SUMPRODUCT((TEXT('01_売上入力'!A3:A200,"YYYY/MM")=A14)*('01_売上入力'!E3:E200)),"") | E14: =IFERROR(IF(D14="","",IF(D14=0,"-",B14/D14)),"") | F14: =IFERROR(SUMPRODUCT((TEXT('04_廃棄入力'!A3:A200,"YYYY/MM")=A14)*('04_廃棄入力'!E3:E200)),"")
B15: =IFERROR(SUMPRODUCT((TEXT('01_売上入力'!A3:A200,"YYYY/MM")=A15)*('01_売上入力'!G3:G200)),"") | C15: =IFERROR(SUMPRODUCT((TEXT('01_売上入力'!A3:A200,"YYYY/MM")=A15)*('01_売上入力'!E3:E200)),"") | E15: =IFERROR(IF(D15="","",IF(D15=0,"-",B15/D15)),"") | F15: =IFERROR(SUMPRODUCT((TEXT('04_廃棄入力'!A3:A200,"YYYY/MM")=A15)*('04_廃棄入力'!E3:E200)),"")
B16: =IFERROR(SUMPRODUCT((TEXT('01_売上入力'!A3:A200,"YYYY/MM")=A16)*('01_売上入力'!G3:G200)),"") | C16: =IFERROR(SUMPRODUCT((TEXT('01_売上入力'!A3:A200,"YYYY/MM")=A16)*('01_売上入力'!E3:E200)),"") | E16: =IFERROR(IF(D16="","",IF(D16=0,"-",B16/D16)),"") | F16: =IFERROR(SUMPRODUCT((TEXT('04_廃棄入力'!A3:A200,"YYYY/MM")=A16)*('04_廃棄入力'!E3:E200)),"")
B17: =IFERROR(SUMPRODUCT((TEXT('01_売上入力'!A3:A200,"YYYY/MM")=A17)*('01_売上入力'!G3:G200)),"") | C17: =IFERROR(SUMPRODUCT((TEXT('01_売上入力'!A3:A200,"YYYY/MM")=A17)*('01_売上入力'!E3:E200)),"") | E17: =IFERROR(IF(D17="","",IF(D17=0,"-",B17/D17)),"") | F17: =IFERROR(SUMPRODUCT((TEXT('04_廃棄入力'!A3:A200,"YYYY/MM")=A17)*('04_廃棄入力'!E3:E200)),"")
B18: =IFERROR(SUMPRODUCT((TEXT('01_売上入力'!A3:A200,"YYYY/MM")=A18)*('01_売上入力'!G3:G200)),"") | C18: =IFERROR(SUMPRODUCT((TEXT('01_売上入力'!A3:A200,"YYYY/MM")=A18)*('01_売上入力'!E3:E200)),"") | E18: =IFERROR(IF(D18="","",IF(D18=0,"-",B18/D18)),"") | F18: =IFERROR(SUMPRODUCT((TEXT('04_廃棄入力'!A3:A200,"YYYY/MM")=A18)*('04_廃棄入力'!E3:E200)),"")
B19: =IFERROR(SUMPRODUCT((TEXT('01_売上入力'!A3:A200,"YYYY/MM")=A19)*('01_売上入力'!G3:G200)),"") | C19: =IFERROR(SUMPRODUCT((TEXT('01_売上入力'!A3:A200,"YYYY/MM")=A19)*('01_売上入力'!E3:E200)),"") | E19: =IFERROR(IF(D19="","",IF(D19=0,"-",B19/D19)),"") | F19: =IFERROR(SUMPRODUCT((TEXT('04_廃棄入力'!A3:A200,"YYYY/MM")=A19)*('04_廃棄入力'!E3:E200)),"")
B20: =IFERROR(SUMPRODUCT((TEXT('01_売上入力'!A3:A200,"YYYY/MM")=A20)*('01_売上入力'!G3:G200)),"") | C20: =IFERROR(SUMPRODUCT((TEXT('01_売上入力'!A3:A200,"YYYY/MM")=A20)*('01_売上入力'!E3:E200)),"") | E20: =IFERROR(IF(D20="","",IF(D20=0,"-",B20/D20)),"") | F20: =IFERROR(SUMPRODUCT((TEXT('04_廃棄入力'!A3:A200,"YYYY/MM")=A20)*('04_廃棄入力'!E3:E200)),"")
B21: =IFERROR(SUMPRODUCT((TEXT('01_売上入力'!A3:A200,"YYYY/MM")=A21)*('01_売上入力'!G3:G200)),"") | C21: =IFERROR(SUMPRODUCT((TEXT('01_売上入力'!A3:A200,"YYYY/MM")=A21)*('01_売上入力'!E3:E200)),"") | E21: =IFERROR(IF(D21="","",IF(D21=0,"-",B21/D21)),"") | F21: =IFERROR(SUMPRODUCT((TEXT('04_廃棄入力'!A3:A200,"YYYY/MM")=A21)*('04_廃棄入力'!E3:E200)),"")
B22: =IFERROR(SUMPRODUCT((TEXT('01_売上入力'!A3:A200,"YYYY/MM")=A22)*('01_売上入力'!G3:G200)),"") | C22: =IFERROR(SUMPRODUCT((TEXT('01_売上入力'!A3:A200,"YYYY/MM")=A22)*('01_売上入力'!E3:E200)),"") | E22: =IFERROR(IF(D22="","",IF(D22=0,"-",B22/D22)),"") | F22: =IFERROR(SUMPRODUCT((TEXT('04_廃棄入力'!A3:A200,"YYYY/MM")=A22)*('04_廃棄入力'!E3:E200)),"")
B23: =IFERROR(SUMPRODUCT((TEXT('01_売上入力'!A3:A200,"YYYY/MM")=A23)*('01_売上入力'!G3:G200)),"") | C23: =IFERROR(SUMPRODUCT((TEXT('01_売上入力'!A3:A200,"YYYY/MM")=A23)*('01_売上入力'!E3:E200)),"") | E23: =IFERROR(IF(D23="","",IF(D23=0,"-",B23/D23)),"") | F23: =IFERROR(SUMPRODUCT((TEXT('04_廃棄入力'!A3:A200,"YYYY/MM")=A23)*('04_廃棄入力'!E3:E200)),"")
B24: =IFERROR(SUMPRODUCT((TEXT('01_売上入力'!A3:A200,"YYYY/MM")=A24)*('01_売上入力'!G3:G200)),"") | C24: =IFERROR(SUMPRODUCT((TEXT('01_売上入力'!A3:A200,"YYYY/MM")=A24)*('01_売上入力'!E3:E200)),"") | E24: =IFERROR(IF(D24="","",IF(D24=0,"-",B24/D24)),"") | F24: =IFERROR(SUMPRODUCT((TEXT('04_廃棄入力'!A3:A200,"YYYY/MM")=A24)*('04_廃棄入力'!E3:E200)),"")
B25: =IFERROR(SUMPRODUCT((TEXT('01_売上入力'!A3:A200,"YYYY/MM")=A25)*('01_売上入力'!G3:G200)),"") | C25: =IFERROR(SUMPRODUCT((TEXT('01_売上入力'!A3:A200,"YYYY/MM")=A25)*('01_売上入力'!E3:E200)),"") | E25: =IFERROR(IF(D25="","",IF(D25=0,"-",B25/D25)),"") | F25: =IFERROR(SUMPRODUCT((TEXT('04_廃棄入力'!A3:A200,"YYYY/MM")=A25)*('04_廃棄入力'!E3:E200)),"")
B26: =IFERROR(SUMPRODUCT((TEXT('01_売上入力'!A3:A200,"YYYY/MM")=A26)*('01_売上入力'!G3:G200)),"") | C26: =IFERROR(SUMPRODUCT((TEXT('01_売上入力'!A3:A200,"YYYY/MM")=A26)*('01_売上入力'!E3:E200)),"") | E26: =IFERROR(IF(D26="","",IF(D26=0,"-",B26/D26)),"") | F26: =IFERROR(SUMPRODUCT((TEXT('04_廃棄入力'!A3:A200,"YYYY/MM")=A26)*('04_廃棄入力'!E3:E200)),"")
B27: =IFERROR(SUMPRODUCT((TEXT('01_売上入力'!A3:A200,"YYYY/MM")=A27)*('01_売上入力'!G3:G200)),"") | C27: =IFERROR(SUMPRODUCT((TEXT('01_売上入力'!A3:A200,"YYYY/MM")=A27)*('01_売上入力'!E3:E200)),"") | E27: =IFERROR(IF(D27="","",IF(D27=0,"-",B27/D27)),"") | F27: =IFERROR(SUMPRODUCT((TEXT('04_廃棄入力'!A3:A200,"YYYY/MM")=A27)*('04_廃棄入力'!E3:E200)),"")
B28: =IFERROR(SUMPRODUCT((TEXT('01_売上入力'!A3:A200,"YYYY/MM")=A28)*('01_売上入力'!G3:G200)),"") | C28: =IFERROR(SUMPRODUCT((TEXT('01_売上入力'!A3:A200,"YYYY/MM")=A28)*('01_売上入力'!E3:E200)),"") | E28: =IFERROR(IF(D28="","",IF(D28=0,"-",B28/D28)),"") | F28: =IFERROR(SUMPRODUCT((TEXT('04_廃棄入力'!A3:A200,"YYYY/MM")=A28)*('04_廃棄入力'!E3:E200)),"")
B29: =IFERROR(SUMPRODUCT((TEXT('01_売上入力'!A3:A200,"YYYY/MM")=A29)*('01_売上入力'!G3:G200)),"") | C29: =IFERROR(SUMPRODUCT((TEXT('01_売上入力'!A3:A200,"YYYY/MM")=A29)*('01_売上入力'!E3:E200)),"") | E29: =IFERROR(IF(D29="","",IF(D29=0,"-",B29/D29)),"") | F29: =IFERROR(SUMPRODUCT((TEXT('04_廃棄入力'!A3:A200,"YYYY/MM")=A29)*('04_廃棄入力'!E3:E200)),"")
B30: =IFERROR(SUMPRODUCT((TEXT('01_売上入力'!A3:A200,"YYYY/MM")=A30)*('01_売上入力'!G3:G200)),"") | C30: =IFERROR(SUMPRODUCT((TEXT('01_売上入力'!A3:A200,"YYYY/MM")=A30)*('01_売上入力'!E3:E200)),"") | E30: =IFERROR(IF(D30="","",IF(D30=0,"-",B30/D30)),"") | F30: =IFERROR(SUMPRODUCT((TEXT('04_廃棄入力'!A3:A200,"YYYY/MM")=A30)*('04_廃棄入力'!E3:E200)),"")
B31: =IFERROR(SUMPRODUCT((TEXT('01_売上入力'!A3:A200,"YYYY/MM")=A31)*('01_売上入力'!G3:G200)),"") | C31: =IFERROR(SUMPRODUCT((TEXT('01_売上入力'!A3:A200,"YYYY/MM")=A31)*('01_売上入力'!E3:E200)),"") | E31: =IFERROR(IF(D31="","",IF(D31=0,"-",B31/D31)),"") | F31: =IFERROR(SUMPRODUCT((TEXT('04_廃棄入力'!A3:A200,"YYYY/MM")=A31)*('04_廃棄入力'!E3:E200)),"")
B32: =IFERROR(SUMPRODUCT((TEXT('01_売上入力'!A3:A200,"YYYY/MM")=A32)*('01_売上入力'!G3:G200)),"") | C32: =IFERROR(SUMPRODUCT((TEXT('01_売上入力'!A3:A200,"YYYY/MM")=A32)*('01_売上入力'!E3:E200)),"") | E32: =IFERROR(IF(D32="","",IF(D32=0,"-",B32/D32)),"") | F32: =IFERROR(SUMPRODUCT((TEXT('04_廃棄入力'!A3:A200,"YYYY/MM")=A32)*('04_廃棄入力'!E3:E200)),"")
B33: =IFERROR(SUMPRODUCT((TEXT('01_売上入力'!A3:A200,"YYYY/MM")=A33)*('01_売上入力'!G3:G200)),"") | C33: =IFERROR(SUMPRODUCT((TEXT('01_売上入力'!A3:A200,"YYYY/MM")=A33)*('01_売上入力'!E3:E200)),"") | E33: =IFERROR(IF(D33="","",IF(D33=0,"-",B33/D33)),"") | F33: =IFERROR(SUMPRODUCT((TEXT('04_廃棄入力'!A3:A200,"YYYY/MM")=A33)*('04_廃棄入力'!E3:E200)),"")
B34: =IFERROR(SUMPRODUCT((TEXT('01_売上入力'!A3:A200,"YYYY/MM")=A34)*('01_売上入力'!G3:G200)),"") | C34: =IFERROR(SUMPRODUCT((TEXT('01_売上入力'!A3:A200,"YYYY/MM")=A34)*('01_売上入力'!E3:E200)),"") | E34: =IFERROR(IF(D34="","",IF(D34=0,"-",B34/D34)),"") | F34: =IFERROR(SUMPRODUCT((TEXT('04_廃棄入力'!A3:A200,"YYYY/MM")=A34)*('04_廃棄入力'!E3:E200)),"")
B35: =IFERROR(SUMPRODUCT((TEXT('01_売上入力'!A3:A200,"YYYY/MM")=A35)*('01_売上入力'!G3:G200)),"") | C35: =IFERROR(SUMPRODUCT((TEXT('01_売上入力'!A3:A200,"YYYY/MM")=A35)*('01_売上入力'!E3:E200)),"") | E35: =IFERROR(IF(D35="","",IF(D35=0,"-",B35/D35)),"") | F35: =IFERROR(SUMPRODUCT((TEXT('04_廃棄入力'!A3:A200,"YYYY/MM")=A35)*('04_廃棄入力'!E3:E200)),"")
B36: =IFERROR(SUMPRODUCT((TEXT('01_売上入力'!A3:A200,"YYYY/MM")=A36)*('01_売上入力'!G3:G200)),"") | C36: =IFERROR(SUMPRODUCT((TEXT('01_売上入力'!A3:A200,"YYYY/MM")=A36)*('01_売上入力'!E3:E200)),"") | E36: =IFERROR(IF(D36="","",IF(D36=0,"-",B36/D36)),"") | F36: =IFERROR(SUMPRODUCT((TEXT('04_廃棄入力'!A3:A200,"YYYY/MM")=A36)*('04_廃棄入力'!E3:E200)),"")
B37: =IFERROR(SUMPRODUCT((TEXT('01_売上入力'!A3:A200,"YYYY/MM")=A37)*('01_売上入力'!G3:G200)),"") | C37: =IFERROR(SUMPRODUCT((TEXT('01_売上入力'!A3:A200,"YYYY/MM")=A37)*('01_売上入力'!E3:E200)),"") | E37: =IFERROR(IF(D37="","",IF(D37=0,"-",B37/D37)),"") | F37: =IFERROR(SUMPRODUCT((TEXT('04_廃棄入力'!A3:A200,"YYYY/MM")=A37)*('04_廃棄入力'!E3:E200)),"")
B38: =IFERROR(SUMPRODUCT((TEXT('01_売上入力'!A3:A200,"YYYY/MM")=A38)*('01_売上入力'!G3:G200)),"") | C38: =IFERROR(SUMPRODUCT((TEXT('01_売上入力'!A3:A200,"YYYY/MM")=A38)*('01_売上入力'!E3:E200)),"") | E38: =IFERROR(IF(D38="","",IF(D38=0,"-",B38/D38)),"") | F38: =IFERROR(SUMPRODUCT((TEXT('04_廃棄入力'!A3:A200,"YYYY/MM")=A38)*('04_廃棄入力'!E3:E200)),"")
B39: =IFERROR(SUMPRODUCT((TEXT('01_売上入力'!A3:A200,"YYYY/MM")=A39)*('01_売上入力'!G3:G200)),"") | C39: =IFERROR(SUMPRODUCT((TEXT('01_売上入力'!A3:A200,"YYYY/MM")=A39)*('01_売上入力'!E3:E200)),"") | E39: =IFERROR(IF(D39="","",IF(D39=0,"-",B39/D39)),"") | F39: =IFERROR(SUMPRODUCT((TEXT('04_廃棄入力'!A3:A200,"YYYY/MM")=A39)*('04_廃棄入力'!E3:E200)),"")
B40: =IFERROR(SUMPRODUCT((TEXT('01_売上入力'!A3:A200,"YYYY/MM")=A40)*('01_売上入力'!G3:G200)),"") | C40: =IFERROR(SUMPRODUCT((TEXT('01_売上入力'!A3:A200,"YYYY/MM")=A40)*('01_売上入力'!E3:E200)),"") | E40: =IFERROR(IF(D40="","",IF(D40=0,"-",B40/D40)),"") | F40: =IFERROR(SUMPRODUCT((TEXT('04_廃棄入力'!A3:A200,"YYYY/MM")=A40)*('04_廃棄入力'!E3:E200)),"")
...

Sheet 08_改善提案
A1: 08 改善提案 ― AIへの貼り付け用・経営課題の整理
A2: 分析区分 | B2: 問題・指標 | C2: 考えられる原因 | D2: 改善案 | E2: 優先度
A3: 利益 | B3: =IFERROR("粗利率最低商品: "&INDEX('02_商品マスタ'!B:B,MATCH(MIN('02_商品マスタ'!I:I),'02_商品マスタ'!I:I,0)),"データなし") | C3: 原価高騰 / 販売価格が低い | D3: 値上げ検討 or 原価見直し | E3: 高
A4: 廃棄 | B4: =IFERROR("廃棄金額合計: "&TEXT(SUM('04_廃棄入力'!E:E),"#,##0")&"円","データなし") | C4: 製造数が需要を上回っている | D4: 製造数を販売実績に合わせて削減 | E4: 高
A5: 製造 | B5: =IFERROR("最も製造時間がかかる商品: "&INDEX('05_製造時間'!A:A,MATCH(MAX('05_製造時間'!E:E),'05_製造時間'!E:E,0)),"データなし") | C5: 工程が複雑 / 人手不足 | D5: 製造工程の見直し or 販売終了検討 | E5: 中
A6: 人件費 | B6: =IFERROR("人件費合計: "&TEXT(SUM('06_人件費'!G:G),"#,##0")&"円","データなし") | C6: シフト過多 / 残業 | D6: 売上ピーク時間帯に集中したシフト設計 | E6: 中
A7: 時間帯 | B7: ピーク時間帯の売上集中確認 | C7: 焼成タイミングとピーク時間がズレている | D7: 時間帯別データを元に焼成スケジュールを調整 | E7: 高
A10: 【Claude / ChatGPT への貼り付け方】 このシートの内容をコピーして以下のプロンプトと一緒に貼り付けてください： 「以下はパン屋の経営データ分析です。改善策を具体的に提案してください。」
